<mujoco model="biped_flatfoot_robot">
  <compiler angle="radian" autolimits="true"/>
  <statistic meansize="0.0767226" extent="0.843944" center="0 0 -0.196972"/>
  <asset>
    <mesh name="base_link" file="base_link.stl"/>
    <mesh name="hip_yaw_link" file="hip_yaw_link.stl"/>
    <mesh name="hip_roll_link" file="hip_roll_link.stl"/>
    <mesh name="thigh_link" file="thigh_link.stl"/>
    <mesh name="knee_link" file="knee_link.stl"/>
    <mesh name="ankle_link" file="ankle_link.stl"/>
    <mesh name="tip_link" file="tip_link.stl"/>
  </asset>
  <worldbody>
    <body name="base_link" pos="-3.99984992e-03  1.40198736e-04  4.93131496e-01" quat="9.98626276e-01 -1.25590195e-05  5.23980567e-02  6.85270599e-05">
      <inertial pos="0 0 0" mass="4.546" diaginertia="0.0676535 0.0534409 0.0172355"/>
      <joint name="base_link_free_joint" type="free"/>
      <geom type="mesh" mesh="base_link"/>
      <body name="right_hip_yaw_link" pos="0 -0.065 -0.175">
        <inertial pos="0 0 0" quat="0 0.707107 0 0.707107" mass="0.108149" diaginertia="5.0357e-05 3.95984e-05 3.95984e-05"/>
        <joint name="right_hip_yaw_joint" pos="0 0 0" axis="0 0 1" range="-2.5 2.5" frictionloss="0.05"/>
        <geom type="mesh" mesh="hip_yaw_link"/>
        <body name="right_hip_roll_link">
          <inertial pos="0 0 0" mass="0.108149" diaginertia="5.0357e-05 3.95984e-05 3.95984e-05"/>
          <joint name="right_hip_roll_joint" pos="0 0 0" axis="1 0 0" range="-2.5 2.5" frictionloss="0.05"/>
          <geom type="mesh" mesh="hip_roll_link"/>
          <body name="right_thigh_link">
            <inertial pos="0 0 -0.09" quat="0.707107 0 0 0.707107" mass="0.12805" diaginertia="0.000525519 0.000525492 2.45411e-05"/>
            <joint name="right_hip_pitch_joint" pos="0 0 0" axis="0 1 0" range="-2.5 2.5" frictionloss="0.05"/>
            <geom type="mesh" mesh="thigh_link"/>
            <body name="right_knee_link" pos="0 0 -0.18">
              <inertial pos="0 0 -0.09" mass="0.123672" diaginertia="0.000345323 0.000345323 2.28175e-05"/>
              <joint name="right_knee_joint" pos="0 0 0" axis="0 1 0" range="-2.5 2.5" frictionloss="0.05"/>
              <geom type="mesh" mesh="knee_link"/>
              <body name="right_ankle_link" pos="0 0 -0.18">
                <inertial pos="0 0 0.01" mass="0.0972" diaginertia="2.025e-05 2.025e-05 1.458e-05"/>
                <joint name="right_ankle_pitch_joint" pos="0 0 0" axis="0 1 0" range="-2.5 2.5" frictionloss="0.05"/>
                <geom type="mesh" mesh="ankle_link"/>
                <body name="right_foot_tip_link">
                  <inertial pos="0.002639 0 -0.011265" quat="0 0.723117 0 0.690725" mass="0.139622" diaginertia="0.000251492 0.000185289 8.09792e-05"/>
                  <joint name="right_ankle_roll_joint" pos="0 0 0" axis="1 0 0" range="-2.5 2.5" frictionloss="0.05"/>
                  <geom type="mesh" mesh="tip_link"/>
                </body>
              </body>
            </body>
          </body>
        </body>
      </body>
      <body name="left_hip_yaw_link" pos="0 0.065 -0.175">
        <inertial pos="0 0 0" quat="0 0.707107 0 0.707107" mass="0.108149" diaginertia="5.0357e-05 3.95984e-05 3.95984e-05"/>
        <joint name="left_hip_yaw_joint" pos="0 0 0" axis="0 0 1" range="-2.5 2.5" frictionloss="0.05"/>
        <geom type="mesh" mesh="hip_yaw_link"/>
        <body name="left_hip_roll_link">
          <inertial pos="0 0 0" mass="0.108149" diaginertia="5.0357e-05 3.95984e-05 3.95984e-05"/>
          <joint name="left_hip_roll_joint" pos="0 0 0" axis="1 0 0" range="-2.5 2.5" frictionloss="0.05"/>
          <geom type="mesh" mesh="hip_roll_link"/>
          <body name="left_thigh_link">
            <inertial pos="0 0 -0.09" quat="0.707107 0 0 0.707107" mass="0.12805" diaginertia="0.000525519 0.000525492 2.45411e-05"/>
            <joint name="left_hip_pitch_joint" pos="0 0 0" axis="0 1 0" range="-2.5 2.5" frictionloss="0.05"/>
            <geom type="mesh" mesh="thigh_link"/>
            <body name="left_knee_link" pos="0 0 -0.18">
              <inertial pos="0 0 -0.09" mass="0.123672" diaginertia="0.000345323 0.000345323 2.28175e-05"/>
              <joint name="left_knee_joint" pos="0 0 0" axis="0 1 0" range="-2.5 2.5" frictionloss="0.05"/>
              <geom type="mesh" mesh="knee_link"/>
              <body name="left_ankle_link" pos="0 0 -0.18">
                <inertial pos="0 0 0.01" mass="0.0972" diaginertia="2.025e-05 2.025e-05 1.458e-05"/>
                <joint name="left_ankle_pitch_joint" pos="0 0 0" axis="0 1 0" range="-2.5 2.5" frictionloss="0.05"/>
                <geom type="mesh" mesh="ankle_link"/>
                <body name="left_foot_tip_link">
                  <inertial pos="0.002639 0 -0.011265" quat="0 0.723117 0 0.690725" mass="0.139622" diaginertia="0.000251492 0.000185289 8.09792e-05"/>
                  <joint name="left_ankle_roll_joint" pos="0 0 0" axis="1 0 0" range="-2.5 2.5" frictionloss="0.05"/>
                  <geom type="mesh" mesh="tip_link"/>
                </body>
              </body>
            </body>
          </body>
        </body>
      </body>
    </body>
  </worldbody>
  <actuator>
    <position joint="right_hip_yaw_joint" name="right_hip_yaw_actuator" gear="1.0"/>
    <position joint="right_hip_roll_joint" name="right_hip_roll_actuator" gear="1.0"/>
    <position joint="right_hip_pitch_joint" name="right_hip_pitch_actuator" gear="1.0"/>
    <position joint="right_knee_joint" name="right_knee_actuator" gear="1.0"/>
    <position joint="right_ankle_pitch_joint" name="right_ankle_pitch_actuator" gear="1.0"/>
    <position joint="right_ankle_roll_joint" name="right_ankle_roll_actuator" gear="1.0"/>
    <position joint="left_hip_yaw_joint" name="left_hip_yaw_actuator" gear="1.0"/>
    <position joint="left_hip_roll_joint" name="left_hip_roll_actuator" gear="1.0"/>
    <position joint="left_hip_pitch_joint" name="left_hip_pitch_actuator" gear="1.0"/>
    <position joint="left_knee_joint" name="left_knee_actuator" gear="1.0"/>
    <position joint="left_ankle_pitch_joint" name="left_ankle_pitch_actuator" gear="1.0"/>
    <position joint="left_ankle_roll_joint" name="left_ankle_roll_actuator" gear="1.0"/>
  </actuator>
</mujoco>
